<?xml version="1.0" ?>
<!-- =================================================================================== -->
<!-- |    This document was autogenerated by xacro from /root/ros_ws/src/amiga_description/robots/urdf/amiga.urdf.xacro | -->
<!-- |    EDITING THIS FILE BY HAND IS NOT RECOMMENDED                                 | -->
<!-- =================================================================================== -->
<robot name="amiga">
  <!-- Authors: Nico Lingg & Cedric Goubard -->
  <!-- Authors: Nico Lingg & Cedric Goubard -->
  <!--
        This file Gazebo-related elements for the base.
        DO NOT USE IT BY ITSELF; it is meant to be imported in quickie_base.urdf.xacro
     -->
  <material name="zed_mat">
    <color rgba="0.8 0.8 0.8 0.8"/>
  </material>
  <material name="zedm_mat">
    <color rgba="0 0 0 0.9"/>
  </material>
  <material name="zed2_mat">
    <color rgba="0.25 0.25 0.25 0.99"/>
  </material>
  <material name="zed2i_mat">
    <color rgba="0.25 0.25 0.25 0.99"/>
  </material>
  <!--
  Author: Kelsey Hawkins
  Contributers: Jimmy Da Silva, Ajit Krisshna N L, Muhammad Asif Rana
-->
  <!-- Authors: Nico Lingg & Cedric Goubard -->
  <!--
        This file Gazebo-related elements for the 3 fingers robotiq gripper.
        DO NOT USE IT BY ITSELF; it is meant to be imported in amiga.urdf.xacro
     -->
  <link name="dummy_link"/>
  <joint name="dummy_joint" type="fixed">
    <parent link="dummy_link"/>
    <child link="base_link"/>
    <origin rpy="0 0 0" xyz="0 0 0"/>
    <axis xyz="0 0 0"/>
  </joint>
  <link name="base_link">
    <inertial>
      <origin rpy="0 0 0" xyz="-0.013975 0.051448 3.6862E-05"/>
      <mass value="110.78"/>
      <!-- <inertia ixx="0.50372" ixy="0.034645" ixz="0.00011003" iyy="3.112" iyz="0.00034085" izz="3.1694" /> -->
      <inertia ixx="2.77527" ixy="0.05" ixz="0.01" iyy="6.491016" iyz="0.01" izz="6.66988"/>
    </inertial>
    <visual>
      <origin rpy="0 0 0" xyz="0 0 0"/>
      <geometry>
        <mesh filename="package://arnie_description/robots/meshes/base_link.STL"/>
      </geometry>
      <material name="">
        <color rgba="1 1 1 1"/>
      </material>
    </visual>
    <collision>
      <origin rpy="0 0 0" xyz="0 0 0"/>
      <geometry>
        <mesh filename="package://arnie_description/robots/meshes/base_link.STL"/>
      </geometry>
    </collision>
  </link>
  <link name="drive_wheel_right">
    <inertial>
      <origin rpy="0 0 0" xyz="-3.4907E-12 0.028895 1.236E-14"/>
      <mass value="3.9607"/>
      <inertia ixx="0.028179" ixy="3.3797E-15" ixz="-1.2302E-12" iyy="0.054226" iyz="-1.2741E-17" izz="0.028179"/>
    </inertial>
    <visual>
      <origin rpy="0 0 0" xyz="0 0 0"/>
      <geometry>
        <mesh filename="package://arnie_description/robots/meshes/drive_wheel_right.STL"/>
      </geometry>
      <material name="">
        <color rgba="0.29804 0.29804 0.29804 1"/>
      </material>
    </visual>
    <collision>
      <origin rpy="0 0 0" xyz="0 0 0"/>
      <geometry>
        <mesh filename="package://arnie_description/robots/meshes/drive_wheel_right.STL"/>
      </geometry>
    </collision>
  </link>
  <joint name="base_drive_wheel_right" type="continuous">
    <origin rpy="0 0 0" xyz="0 0.1995 0"/>
    <parent link="base_link"/>
    <child link="drive_wheel_right"/>
    <axis xyz="0 1 0"/>
  </joint>
  <link name="drive_wheel_left">
    <inertial>
      <origin rpy="0 0 0" xyz="-3.4906E-12 0.028895 1.2374E-14"/>
      <mass value="3.9607"/>
      <inertia ixx="0.028179" ixy="3.3837E-15" ixz="-1.2302E-12" iyy="0.054226" iyz="-1.3611E-17" izz="0.028179"/>
    </inertial>
    <visual>
      <origin rpy="0 0 0" xyz="0 0 0"/>
      <geometry>
        <mesh filename="package://arnie_description/robots/meshes/drive_wheel_left.STL"/>
      </geometry>
      <material name="">
        <color rgba="0.29804 0.29804 0.29804 1"/>
      </material>
    </visual>
    <collision>
      <origin rpy="0 0 0" xyz="0 0 0"/>
      <geometry>
        <mesh filename="package://arnie_description/robots/meshes/drive_wheel_left.STL"/>
      </geometry>
    </collision>
  </link>
  <joint name="base_drive_wheel_left" type="continuous">
    <origin rpy="3.1416 0 0" xyz="0 -0.1995 0"/>
    <parent link="base_link"/>
    <child link="drive_wheel_left"/>
    <axis xyz="0 -1 0"/>
  </joint>
  <link name="castor_front_left">
    <inertial>
      <origin rpy="0 0 0" xyz="0.010525 -0.0097266 7.7108E-08"/>
      <mass value="0.20821"/>
      <inertia ixx="0.00055537" ixy="8.8662E-05" ixz="8.9051E-11" iyy="0.00024751" iyz="1.6993E-09" izz="0.00042332"/>
    </inertial>
    <visual>
      <origin rpy="0 0 0" xyz="0 0 0"/>
      <geometry>
        <mesh filename="package://arnie_description/robots/meshes/castor_front_left.STL"/>
      </geometry>
      <material name="">
        <color rgba="0.19216 0.20392 0.20392 1"/>
      </material>
    </visual>
    <collision>
      <origin rpy="0 0 0" xyz="0 0 0"/>
      <geometry>
        <mesh filename="package://arnie_description/robots/meshes/castor_front_left.STL"/>
      </geometry>
    </collision>
  </link>
  <joint name="base_to_castor_front_left" type="continuous">
    <origin rpy="1.5708 0 3.1416" xyz="-0.38799 -0.17127 0"/>
    <parent link="base_link"/>
    <child link="castor_front_left"/>
    <axis xyz="0 1 0"/>
  </joint>
  <link name="front_wheel_left">
    <inertial>
      <origin rpy="0 0 0" xyz="5.5511E-17 -4.3723E-13 1.5266E-16"/>
      <mass value="1.1217"/>
      <inertia ixx="0.0024847" ixy="2.8893E-15" ixz="3.8142E-20" iyy="0.0045217" iyz="-3.3191E-19" izz="0.0024847"/>
    </inertial>
    <visual>
      <origin rpy="0 0 0" xyz="0 0 0"/>
      <geometry>
        <mesh filename="package://arnie_description/robots/meshes/front_wheel_left.STL"/>
      </geometry>
      <material name="">
        <color rgba="0.89412 0.89412 0.89412 1"/>
      </material>
    </visual>
    <collision>
      <origin rpy="0 0 0" xyz="0 0 0"/>
      <geometry>
        <mesh filename="package://arnie_description/robots/meshes/front_wheel_left.STL"/>
      </geometry>
    </collision>
  </link>
  <joint name="castor_to_front_wheel_left" type="continuous">
    <origin rpy="1.5708 0 3.1416" xyz="0.026228 -0.0725 0"/>
    <parent link="castor_front_left"/>
    <child link="front_wheel_left"/>
    <axis xyz="0 1 0"/>
  </joint>
  <link name="castor_front_right">
    <inertial>
      <origin rpy="0 0 0" xyz="0.010525 -0.0097266 7.7108E-08"/>
      <mass value="0.59378"/>
      <inertia ixx="0.0015838" ixy="0.00025285" ixz="2.5396E-10" iyy="0.00070588" iyz="4.8462E-09" izz="0.0012073"/>
    </inertial>
    <visual>
      <origin rpy="0 0 0" xyz="0 0 0"/>
      <geometry>
        <mesh filename="package://arnie_description/robots/meshes/castor_front_right.STL"/>
      </geometry>
      <material name="">
        <color rgba="0.058824 0.058824 0.058824 1"/>
      </material>
    </visual>
    <collision>
      <origin rpy="0 0 0" xyz="0 0 0"/>
      <geometry>
        <mesh filename="package://arnie_description/robots/meshes/castor_front_right.STL"/>
      </geometry>
    </collision>
  </link>
  <joint name="base_to_castor_front_right" type="continuous">
    <origin rpy="1.5708 0 3.1416" xyz="-0.38799 0.17127 0"/>
    <parent link="base_link"/>
    <child link="castor_front_right"/>
    <axis xyz="0 1 0"/>
  </joint>
  <link name="front_wheel_right">
    <inertial>
      <origin rpy="0 0 0" xyz="-5.5511E-17 -4.3723E-13 1.9429E-16"/>
      <mass value="1.1217"/>
      <inertia ixx="0.0024847" ixy="8.549E-18" ixz="1.0955E-20" iyy="0.0045217" iyz="-3.8877E-20" izz="0.0024847"/>
    </inertial>
    <visual>
      <origin rpy="0 0 0" xyz="0 0 0"/>
      <geometry>
        <mesh filename="package://arnie_description/robots/meshes/front_wheel_right.STL"/>
      </geometry>
      <material name="">
        <color rgba="0.89412 0.89412 0.89412 1"/>
      </material>
    </visual>
    <collision>
      <origin rpy="0 0 0" xyz="0 0 0"/>
      <geometry>
        <mesh filename="package://arnie_description/robots/meshes/front_wheel_right.STL"/>
      </geometry>
    </collision>
  </link>
  <joint name="castor_to_front_wheel_right" type="continuous">
    <origin rpy="1.5708 0 3.1416" xyz="0.026228 -0.0725 0"/>
    <parent link="castor_front_right"/>
    <child link="front_wheel_right"/>
    <axis xyz="0 1 0"/>
  </joint>
  <link name="castor_back_right">
    <inertial>
      <origin rpy="0 0 0" xyz="0.010525 -0.0097266 7.7108E-08"/>
      <mass value="0.59378"/>
      <inertia ixx="0.0015838" ixy="0.00025285" ixz="2.5396E-10" iyy="0.00070588" iyz="4.8462E-09" izz="0.0012073"/>
    </inertial>
    <visual>
      <origin rpy="0 0 0" xyz="0 0 0"/>
      <geometry>
        <mesh filename="package://arnie_description/robots/meshes/castor_back_right.STL"/>
      </geometry>
      <material name="">
        <color rgba="0.058824 0.058824 0.058824 1"/>
      </material>
    </visual>
    <collision>
      <origin rpy="0 0 0" xyz="0 0 0"/>
      <geometry>
        <mesh filename="package://arnie_description/robots/meshes/castor_back_right.STL"/>
      </geometry>
    </collision>
  </link>
  <joint name="base_to_castor_back_right" type="continuous">
    <origin rpy="1.5708 0 0" xyz="0.33036 0.225 0"/>
    <parent link="base_link"/>
    <child link="castor_back_right"/>
    <axis xyz="0 1 0"/>
  </joint>
  <link name="back_wheel_right">
    <inertial>
      <origin rpy="0 0 0" xyz="-5.55111512312578E-17 -4.37178071521771E-13 1.80411241501588E-16"/>
      <mass value="1.1217362251687"/>
      <inertia ixx="0.00248469116365274" ixy="4.33111862479103E-18" ixz="8.98605873919767E-21" iyy="0.00452169778229441" iyz="-1.22844801633355E-14" izz="0.00248469116365274"/>
    </inertial>
    <visual>
      <origin rpy="0 0 0" xyz="0 0 0"/>
      <geometry>
        <mesh filename="package://arnie_description/robots/meshes/back_wheel_right.STL"/>
      </geometry>
      <material name="">
        <color rgba="0.894117647058823 0.894117647058823 0.894117647058823 1"/>
      </material>
    </visual>
    <collision>
      <origin rpy="0 0 0" xyz="0 0 0"/>
      <geometry>
        <mesh filename="package://arnie_description/robots/meshes/back_wheel_right.STL"/>
      </geometry>
    </collision>
  </link>
  <joint name="castor_to_back_wheel_right" type="continuous">
    <origin rpy="1.5708 0 0" xyz="0.026228 -0.0725 0"/>
    <parent link="castor_back_right"/>
    <child link="back_wheel_right"/>
    <axis xyz="0 1 0"/>
  </joint>
  <link name="castor_back_left">
    <inertial>
      <origin rpy="0 0 0" xyz="0.010525 -0.0097266 7.7108E-08"/>
      <mass value="0.59378"/>
      <inertia ixx="0.0015838" ixy="0.00025285" ixz="2.5396E-10" iyy="0.00070588" iyz="4.8462E-09" izz="0.0012073"/>
    </inertial>
    <visual>
      <origin rpy="0 0 0" xyz="0 0 0"/>
      <geometry>
        <mesh filename="package://arnie_description/robots/meshes/castor_back_left.STL"/>
      </geometry>
      <material name="">
        <color rgba="0.058824 0.058824 0.058824 1"/>
      </material>
    </visual>
    <collision>
      <origin rpy="0 0 0" xyz="0 0 0"/>
      <geometry>
        <mesh filename="package://arnie_description/robots/meshes/castor_back_left.STL"/>
      </geometry>
    </collision>
  </link>
  <joint name="base_to_castor_back_left" type="continuous">
    <origin rpy="1.5708 0 0" xyz="0.33036 -0.225 0"/>
    <parent link="base_link"/>
    <child link="castor_back_left"/>
    <axis xyz="0 1 0"/>
  </joint>
  <link name="back_wheel_left">
    <inertial>
      <origin rpy="0 0 0" xyz="0 -4.3721E-13 1.6653E-16"/>
      <mass value="1.1217"/>
      <inertia ixx="0.0024847" ixy="4.3311E-18" ixz="8.9861E-21" iyy="0.0045217" iyz="-1.2284E-14" izz="0.0024847"/>
    </inertial>
    <visual>
      <origin rpy="0 0 0" xyz="0 0 0"/>
      <geometry>
        <mesh filename="package://arnie_description/robots/meshes/back_wheel_left.STL"/>
      </geometry>
      <material name="">
        <color rgba="0.89412 0.89412 0.89412 1"/>
      </material>
    </visual>
    <collision>
      <origin rpy="0 0 0" xyz="0 0 0"/>
      <geometry>
        <mesh filename="package://arnie_description/robots/meshes/back_wheel_left.STL"/>
      </geometry>
    </collision>
  </link>
  <joint name="castor_to_back_wheel_left" type="continuous">
    <origin rpy="1.5708 0 0" xyz="0.026228 -0.0725 0"/>
    <parent link="castor_back_left"/>
    <child link="back_wheel_left"/>
    <axis xyz="0 1 0"/>
  </joint>
  <link name="l515_l_link">
    <visual>
      <origin rpy="1.5707963267948966 0 1.5707963267948966" xyz="0.0045 0 0.009"/>
      <geometry>
        <mesh filename="package://arnie_description/robots/meshes/l515.dae"/>
      </geometry>
    </visual>
    <collision>
      <origin rpy="1.5707963267948966 0 1.5707963267948966" xyz="-0.0055 0 0.009"/>
      <geometry>
        <cylinder length="0.026" radius="0.0305"/>
      </geometry>
    </collision>
    <inertial>
      <mass value="0.095"/>
      <origin xyz="0 0 0"/>
      <inertia ixx="0.000044" ixy="0.0" ixz="0.0" iyy="0.000027" iyz="0.0" izz="0.000027"/>
    </inertial>
  </link>
  <link name="l515_r_link">
    <visual>
      <origin rpy="1.5707963267948966 0 1.5707963267948966" xyz="0.0045 0 0.009"/>
      <geometry>
        <mesh filename="package://arnie_description/robots/meshes/l515.dae"/>
      </geometry>
    </visual>
    <collision>
      <origin rpy="1.5707963267948966 0 1.5707963267948966" xyz="-0.0055 0 0.009"/>
      <geometry>
        <cylinder length="0.026" radius="0.0305"/>
      </geometry>
    </collision>
    <inertial>
      <mass value="0.095"/>
      <origin xyz="0 0 0"/>
      <inertia ixx="0.000044" ixy="0.0" ixz="0.0" iyy="0.000027" iyz="0.0" izz="0.000027"/>
    </inertial>
  </link>
  <material name="grey">
    <color rgba="0.5 0.5 0.5 1"/>
  </material>
  <link name="t265_link">
    <visual>
      <origin rpy="0 0 0" xyz="0 0 0"/>
      <geometry>
        <mesh filename="package://arnie_description/robots/meshes/t265.stl" scale="0.001 0.001 0.001"/>
      </geometry>
      <material name="grey"/>
    </visual>
    <collision>
      <origin rpy="0 0 0" xyz="0 0 0"/>
      <geometry>
        <mesh filename="package://arnie_description/robots/meshes/t265.stl" scale="0.001 0.001 0.001"/>
      </geometry>
      <material name="grey"/>
    </collision>
    <inertial>
      <mass value="0.068024"/>
      <origin xyz="0 0 0"/>
      <inertia ixx="0.0000039782" ixy="0.0" ixz="0.000000034641" iyy="0.000065045" iyz="0.0" izz="0.000067499"/>
    </inertial>
  </link>
  <!-- Camera mounting point (the threaded screw hole in the bottom) -->
  <link name="base_zed2_base_link"/>
  <joint name="base_zed2_base_joint" type="fixed">
    <parent link="base_link"/>
    <child link="base_zed2_base_link"/>
    <origin rpy="0 0 0" xyz="0.31 0 0.25"/>
  </joint>
  <!-- Camera Center -->
  <link name="base_zed2_camera_center">
    <visual>
      <origin rpy="0 0 0" xyz="0.0 0 0"/>
      <geometry>
        <mesh filename="package://amiga_description/robots/meshes/zed2.stl"/>
      </geometry>
      <material name="zed2_mat"/>
    </visual>
    <collision>
      <geometry>
        <mesh filename="package://amiga_description/robots/meshes/zed2.stl"/>
      </geometry>
    </collision>
  </link>
  <joint name="base_zed2_camera_center_joint" type="fixed">
    <parent link="base_zed2_base_link"/>
    <child link="base_zed2_camera_center"/>
    <origin rpy="0 0.05 0" xyz="0 0 0.015"/>
  </joint>
  <!-- Left Camera -->
  <link name="base_zed2_left_camera_frame"/>
  <joint name="base_zed2_left_camera_joint" type="fixed">
    <parent link="base_zed2_camera_center"/>
    <child link="base_zed2_left_camera_frame"/>
    <origin rpy="0 0 0" xyz="0 0.06 0"/>
  </joint>
  <link name="base_zed2_left_camera_optical_frame"/>
  <joint name="base_zed2_left_camera_optical_joint" type="fixed">
    <origin rpy="-1.5707963267948966 0.0 -1.5707963267948966" xyz="-0.01 0 0"/>
    <parent link="base_zed2_left_camera_frame"/>
    <child link="base_zed2_left_camera_optical_frame"/>
  </joint>
  <!-- Right Camera -->
  <link name="base_zed2_right_camera_frame"/>
  <joint name="base_zed2_right_camera_joint" type="fixed">
    <parent link="base_zed2_camera_center"/>
    <child link="base_zed2_right_camera_frame"/>
    <origin rpy="0 0 0" xyz="0 -0.06 0"/>
  </joint>
  <link name="base_zed2_right_camera_optical_frame"/>
  <joint name="base_zed2_right_camera_optical_joint" type="fixed">
    <origin rpy="-1.5707963267948966 0.0 -1.5707963267948966" xyz="-0.01 0 0"/>
    <parent link="base_zed2_right_camera_frame"/>
    <child link="base_zed2_right_camera_optical_frame"/>
  </joint>
  <link name="base_zed2_mag_link"/>
  <joint name="base_zed2_mag_joint" type="fixed">
    <parent link="base_zed2_camera_center"/>
    <child link="base_zed2_mag_link"/>
    <origin rpy="0 0 0" xyz="0 0 0"/>
  </joint>
  <link name="base_zed2_baro_link"/>
  <joint name="base_zed2_baro_joint" type="fixed">
    <parent link="base_zed2_camera_center"/>
    <child link="base_zed2_baro_link"/>
    <origin rpy="0 0 0" xyz="0 0 0"/>
  </joint>
  <link name="base_zed2_temp_left_link"/>
  <joint name="base_zed2_temp_left_joint" type="fixed">
    <parent link="base_zed2_left_camera_frame"/>
    <child link="base_zed2_temp_left_link"/>
    <origin rpy="0 0 0" xyz="0 0 0"/>
  </joint>
  <link name="base_zed2_temp_right_link"/>
  <joint name="base_zed2_temp_right_joint" type="fixed">
    <parent link="base_zed2_right_camera_frame"/>
    <child link="base_zed2_temp_right_link"/>
    <origin rpy="0 0 0" xyz="0 0 0"/>
  </joint>
  <joint name="l515_r_joint" type="fixed">
    <!-- Visual Alignment -->
    <!-- <origin xyz="0.3065 -0.1113 0.201" rpy="0 0 ${-pi/6}" /> -->
    <!-- Feb 2022 -->
    <!-- <origin xyz="0.29600000000000004 0.007068965517241383 0.3083793103448276" rpy="-0.03800000000000001 0.04444827586206899 -0.6248620689655173" /> -->
    <!-- March 2022 -->
    <!-- <origin xyz="0.357075 -0.035125 0.22597500000000004" rpy="-0.006400000000000001 0.001225 -0.601525" /> -->
    <origin rpy="-0.006000000000000004 -0.014145454545454557 -0.49723636363636364" xyz="0.2870000000000002 -0.13287272727272728 0.1902545454545453"/>
    <axis xyz="0 0 0"/>
    <parent link="base_link"/>
    <child link="l515_r_link"/>
  </joint>
  <joint name="l515_l_joint" type="fixed">
    <!-- Visual Alignment -->
    <!-- <origin xyz="0.3065 0.1103 0.201" rpy="0 0 ${pi/6}" />  -->
    <!-- Feb 2022 -->
    <!-- <origin xyz="0.3137931034482758 0.16931034482758614 0.2523448275862068" rpy="-0.009482758620689659 -0.01137931034482759 0.47531034482758583" /> -->
    <!-- March 2022 -->
    <!-- <origin xyz="0.32282500000000003 0.034624999999999996 0.2552000000000001" rpy="0.004800000000000003 -0.003675 0.601975" /> -->
    <origin rpy="0.012175438596491237 0.009491228070175443 0.4976140350877191" xyz="0.31296491228070187 0.13285964912280704 0.22984210526315776"/>
    <axis xyz="0 0 0"/>
    <parent link="base_link"/>
    <child link="l515_l_link"/>
  </joint>
  <joint name="t265_joint" type="fixed">
    <!-- Visual Alignment -->
    <!-- <origin xyz="0.3336 0.001 0.195" rpy="0 0 0" />  -->
    <!-- Feb 2022 -->
    <!--<origin xyz="0.3399999999999999 0.0 0.24000000000000016" rpy="0.0 0.0 0.0" /> -->
    <!-- March 2022 -->
    <!-- <origin xyz="0.39000000000000024 0.0 0.13999999999999996" rpy="0.0 0.0 0.0" /> -->
    <origin rpy="0.0 0.0 0.0" xyz="0.34 0.0 0.2"/>
    <axis xyz="0 0 0"/>
    <parent link="base_link"/>
    <child link="t265_link"/>
  </joint>
  <link name="amiga_arm_base_link">
    <visual>
      <geometry>
        <mesh filename="package://ur_description/meshes/ur10e/visual/base.dae"/>
      </geometry>
      <material name="LightGrey">
        <color rgba="0.7 0.7 0.7 1.0"/>
      </material>
    </visual>
    <collision>
      <geometry>
        <mesh filename="package://ur_description/meshes/ur10e/collision/base.stl"/>
      </geometry>
    </collision>
    <inertial>
      <mass value="4.0"/>
      <origin rpy="0 0 0" xyz="0.0 0.0 0.0"/>
      <inertia ixx="0.0061063308908" ixy="0.0" ixz="0.0" iyy="0.0061063308908" iyz="0.0" izz="0.01125"/>
    </inertial>
  </link>
  <joint name="amiga_arm_shoulder_pan_joint" type="revolute">
    <parent link="amiga_arm_base_link"/>
    <child link="amiga_arm_shoulder_link"/>
    <origin rpy="0.0 0.0 0.0" xyz="0.0 0.0 0.181"/>
    <axis xyz="0 0 1"/>
    <limit effort="330.0" lower="-3.141592653589793" upper="3.141592653589793" velocity="3.14"/>
    <dynamics damping="0.0" friction="0.0"/>
  </joint>
  <link name="amiga_arm_shoulder_link">
    <visual>
      <geometry>
        <mesh filename="package://ur_description/meshes/ur10e/visual/shoulder.dae"/>
      </geometry>
      <material name="LightGrey">
        <color rgba="0.7 0.7 0.7 1.0"/>
      </material>
    </visual>
    <collision>
      <geometry>
        <mesh filename="package://ur_description/meshes/ur10e/collision/shoulder.stl"/>
      </geometry>
    </collision>
    <inertial>
      <mass value="7.778"/>
      <origin rpy="0 0 0" xyz="0.0 0.0 0.0"/>
      <inertia ixx="0.03147431257693659" ixy="0.0" ixz="0.0" iyy="0.03147431257693659" iyz="0.0" izz="0.021875624999999996"/>
    </inertial>
  </link>
  <joint name="amiga_arm_shoulder_lift_joint" type="revolute">
    <parent link="amiga_arm_shoulder_link"/>
    <child link="amiga_arm_upper_arm_link"/>
    <origin rpy="0.0 1.5707963267948966 0.0" xyz="0.0 0.176 0.0"/>
    <axis xyz="0 1 0"/>
    <limit effort="330.0" lower="-3.141592653589793" upper="3.141592653589793" velocity="3.14"/>
    <dynamics damping="0.0" friction="0.0"/>
  </joint>
  <link name="amiga_arm_upper_arm_link">
    <visual>
      <geometry>
        <mesh filename="package://ur_description/meshes/ur10e/visual/upperarm.dae"/>
      </geometry>
      <material name="LightGrey">
        <color rgba="0.7 0.7 0.7 1.0"/>
      </material>
    </visual>
    <collision>
      <geometry>
        <mesh filename="package://ur_description/meshes/ur10e/collision/upperarm.stl"/>
      </geometry>
    </collision>
    <inertial>
      <mass value="12.93"/>
      <origin rpy="0 0 0" xyz="0.0 0.0 0.3065"/>
      <inertia ixx="0.4230737407704359" ixy="0.0" ixz="0.0" iyy="0.4230737407704359" iyz="0.0" izz="0.03636562499999999"/>
    </inertial>
  </link>
  <joint name="amiga_arm_elbow_joint" type="revolute">
    <parent link="amiga_arm_upper_arm_link"/>
    <child link="amiga_arm_forearm_link"/>
    <origin rpy="0.0 0.0 0.0" xyz="0.0 -0.137 0.613"/>
    <axis xyz="0 1 0"/>
    <limit effort="150.0" lower="-3.141592653589793" upper="3.141592653589793" velocity="3.14"/>
    <dynamics damping="0.0" friction="0.0"/>
  </joint>
  <link name="amiga_arm_forearm_link">
    <visual>
      <geometry>
        <mesh filename="package://ur_description/meshes/ur10e/visual/forearm.dae"/>
      </geometry>
      <material name="LightGrey">
        <color rgba="0.7 0.7 0.7 1.0"/>
      </material>
    </visual>
    <collision>
      <geometry>
        <mesh filename="package://ur_description/meshes/ur10e/collision/forearm.stl"/>
      </geometry>
    </collision>
    <inertial>
      <mass value="3.87"/>
      <origin rpy="0 0 0" xyz="0.0 0.0 0.2855"/>
      <inertia ixx="0.11059036576383598" ixy="0.0" ixz="0.0" iyy="0.11059036576383598" iyz="0.0" izz="0.010884375"/>
    </inertial>
  </link>
  <joint name="amiga_arm_wrist_1_joint" type="revolute">
    <parent link="amiga_arm_forearm_link"/>
    <child link="amiga_arm_wrist_1_link"/>
    <origin rpy="0.0 1.5707963267948966 0.0" xyz="0.0 0.0 0.571"/>
    <axis xyz="0 1 0"/>
    <limit effort="54.0" lower="-3.141592653589793" upper="3.141592653589793" velocity="6.28"/>
    <dynamics damping="0.0" friction="0.0"/>
  </joint>
  <link name="amiga_arm_wrist_1_link">
    <visual>
      <geometry>
        <mesh filename="package://ur_description/meshes/ur10e/visual/wrist1.dae"/>
      </geometry>
      <material name="LightGrey">
        <color rgba="0.7 0.7 0.7 1.0"/>
      </material>
    </visual>
    <collision>
      <geometry>
        <mesh filename="package://ur_description/meshes/ur10e/collision/wrist1.stl"/>
      </geometry>
    </collision>
    <inertial>
      <mass value="1.96"/>
      <origin rpy="0 0 0" xyz="0.0 0.135 0.0"/>
      <inertia ixx="0.005108247956699999" ixy="0.0" ixz="0.0" iyy="0.005108247956699999" iyz="0.0" izz="0.005512499999999999"/>
    </inertial>
  </link>
  <joint name="amiga_arm_wrist_2_joint" type="revolute">
    <parent link="amiga_arm_wrist_1_link"/>
    <child link="amiga_arm_wrist_2_link"/>
    <origin rpy="0.0 0.0 0.0" xyz="0.0 0.135 0.0"/>
    <axis xyz="0 0 1"/>
    <limit effort="54.0" lower="-3.141592653589793" upper="3.141592653589793" velocity="6.28"/>
    <dynamics damping="0.0" friction="0.0"/>
  </joint>
  <link name="amiga_arm_wrist_2_link">
    <visual>
      <geometry>
        <mesh filename="package://ur_description/meshes/ur10e/visual/wrist2.dae"/>
      </geometry>
      <material name="LightGrey">
        <color rgba="0.7 0.7 0.7 1.0"/>
      </material>
    </visual>
    <collision>
      <geometry>
        <mesh filename="package://ur_description/meshes/ur10e/collision/wrist2.stl"/>
      </geometry>
    </collision>
    <inertial>
      <mass value="1.96"/>
      <origin rpy="0 0 0" xyz="0.0 0.0 0.12"/>
      <inertia ixx="0.005108247956699999" ixy="0.0" ixz="0.0" iyy="0.005108247956699999" iyz="0.0" izz="0.005512499999999999"/>
    </inertial>
  </link>
  <joint name="amiga_arm_wrist_3_joint" type="revolute">
    <parent link="amiga_arm_wrist_2_link"/>
    <child link="amiga_arm_wrist_3_link"/>
    <origin rpy="0.0 0.0 0.0" xyz="0.0 0.0 0.12"/>
    <axis xyz="0 1 0"/>
    <limit effort="54.0" lower="-3.141592653589793" upper="3.141592653589793" velocity="6.28"/>
    <dynamics damping="0.0" friction="0.0"/>
  </joint>
  <link name="amiga_arm_wrist_3_link">
    <visual>
      <geometry>
        <mesh filename="package://ur_description/meshes/ur10e/visual/wrist3.dae"/>
      </geometry>
      <material name="LightGrey">
        <color rgba="0.7 0.7 0.7 1.0"/>
      </material>
    </visual>
    <collision>
      <geometry>
        <mesh filename="package://ur_description/meshes/ur10e/collision/wrist3.stl"/>
      </geometry>
    </collision>
    <inertial>
      <mass value="0.202"/>
      <origin rpy="1.5707963267948966 0 0" xyz="0.0 0.092 0.0"/>
      <inertia ixx="0.00014434577559500002" ixy="0.0" ixz="0.0" iyy="0.00014434577559500002" iyz="0.0" izz="0.00020452500000000002"/>
    </inertial>
  </link>
  <joint name="amiga_arm_ee_fixed_joint" type="fixed">
    <parent link="amiga_arm_wrist_3_link"/>
    <child link="amiga_arm_ee_link"/>
    <origin rpy="0.0 0.0 1.5707963267948966" xyz="0.0 0.117 0.0"/>
  </joint>
  <link name="amiga_arm_ee_link">
    <collision>
      <geometry>
        <box size="0.01 0.01 0.01"/>
      </geometry>
      <origin rpy="0 0 0" xyz="-0.01 0 0"/>
    </collision>
  </link>
  <transmission name="amiga_arm_shoulder_pan_trans">
    <type>transmission_interface/SimpleTransmission</type>
    <joint name="amiga_arm_shoulder_pan_joint">
      <hardwareInterface>hardware_interface/PositionJointInterface</hardwareInterface>
    </joint>
    <actuator name="amiga_arm_shoulder_pan_motor">
      <mechanicalReduction>1</mechanicalReduction>
    </actuator>
  </transmission>
  <transmission name="amiga_arm_shoulder_lift_trans">
    <type>transmission_interface/SimpleTransmission</type>
    <joint name="amiga_arm_shoulder_lift_joint">
      <hardwareInterface>hardware_interface/PositionJointInterface</hardwareInterface>
    </joint>
    <actuator name="amiga_arm_shoulder_lift_motor">
      <mechanicalReduction>1</mechanicalReduction>
    </actuator>
  </transmission>
  <transmission name="amiga_arm_elbow_trans">
    <type>transmission_interface/SimpleTransmission</type>
    <joint name="amiga_arm_elbow_joint">
      <hardwareInterface>hardware_interface/PositionJointInterface</hardwareInterface>
    </joint>
    <actuator name="amiga_arm_elbow_motor">
      <mechanicalReduction>1</mechanicalReduction>
    </actuator>
  </transmission>
  <transmission name="amiga_arm_wrist_1_trans">
    <type>transmission_interface/SimpleTransmission</type>
    <joint name="amiga_arm_wrist_1_joint">
      <hardwareInterface>hardware_interface/PositionJointInterface</hardwareInterface>
    </joint>
    <actuator name="amiga_arm_wrist_1_motor">
      <mechanicalReduction>1</mechanicalReduction>
    </actuator>
  </transmission>
  <transmission name="amiga_arm_wrist_2_trans">
    <type>transmission_interface/SimpleTransmission</type>
    <joint name="amiga_arm_wrist_2_joint">
      <hardwareInterface>hardware_interface/PositionJointInterface</hardwareInterface>
    </joint>
    <actuator name="amiga_arm_wrist_2_motor">
      <mechanicalReduction>1</mechanicalReduction>
    </actuator>
  </transmission>
  <transmission name="amiga_arm_wrist_3_trans">
    <type>transmission_interface/SimpleTransmission</type>
    <joint name="amiga_arm_wrist_3_joint">
      <hardwareInterface>hardware_interface/PositionJointInterface</hardwareInterface>
    </joint>
    <actuator name="amiga_arm_wrist_3_motor">
      <mechanicalReduction>1</mechanicalReduction>
    </actuator>
  </transmission>
  <gazebo reference="amiga_arm_shoulder_link">
    <selfCollide>true</selfCollide>
  </gazebo>
  <gazebo reference="amiga_arm_upper_arm_link">
    <selfCollide>true</selfCollide>
  </gazebo>
  <gazebo reference="amiga_arm_forearm_link">
    <selfCollide>true</selfCollide>
  </gazebo>
  <gazebo reference="amiga_arm_wrist_1_link">
    <selfCollide>false</selfCollide>
  </gazebo>
  <gazebo reference="amiga_arm_wrist_3_link">
    <selfCollide>false</selfCollide>
  </gazebo>
  <gazebo reference="amiga_arm_wrist_2_link">
    <selfCollide>false</selfCollide>
  </gazebo>
  <gazebo reference="amiga_arm_ee_link">
    <selfCollide>false</selfCollide>
  </gazebo>
  <!-- ROS base_link to UR 'Base' Coordinates transform -->
  <link name="amiga_arm_base"/>
  <joint name="amiga_arm_base_link-base_fixed_joint" type="fixed">
    <!-- NOTE: this rotation is only needed as long as base_link itself is
                 not corrected wrt the real robot (ie: rotated over 180
                 degrees)
      -->
    <origin rpy="0 0 -3.141592653589793" xyz="0 0 0"/>
    <parent link="amiga_arm_base_link"/>
    <child link="amiga_arm_base"/>
  </joint>
  <!-- Frame coincident with all-zeros TCP on UR controller -->
  <link name="amiga_arm_tool0"/>
  <joint name="amiga_arm_wrist_3_link-tool0_fixed_joint" type="fixed">
    <origin rpy="-1.5707963267948966 0 0" xyz="0 0.117 0"/>
    <parent link="amiga_arm_wrist_3_link"/>
    <child link="amiga_arm_tool0"/>
  </joint>
  <!-- link list -->
  <link name="amiga_gripper_finger_1_link_0">
    <visual>
      <origin rpy="0 0 0" xyz="0.020 0 0"/>
      <geometry>
        <mesh filename="package://robotiq_3f_gripper_visualization/meshes/robotiq-3f-gripper_articulated/visual/link_0.dae"/>
      </geometry>
      <material name="gray">
        <color rgba="0.2 0.2 0.2 1"/>
      </material>
    </visual>
    <collision>
      <origin rpy="0 0 0" xyz="0.020 0 0"/>
      <geometry>
        <mesh filename="package://robotiq_3f_gripper_visualization/meshes/robotiq-3f-gripper_articulated/collision/link_0.STL"/>
      </geometry>
      <material name="yellow">
        <color rgba="0 1 1 1"/>
      </material>
    </collision>
    <inertial>
      <origin rpy="0 0 0" xyz="0 0 0"/>
      <mass value="0.05"/>
      <inertia ixx="0.01" ixy="-0.00002" ixz="0.00001" iyy="0.0008" iyz="0" izz="0.001"/>
    </inertial>
  </link>
  <link name="amiga_gripper_finger_1_link_1">
    <visual>
      <origin rpy="0 0 -0.52" xyz="0.050 -.028 0"/>
      <geometry>
        <mesh filename="package://robotiq_3f_gripper_visualization/meshes/robotiq-3f-gripper_articulated/visual/link_1.dae"/>
      </geometry>
      <material name="gray"/>
    </visual>
    <collision>
      <origin rpy="0 0 -0.52" xyz="0.050 -.028 0"/>
      <geometry>
        <mesh filename="package://robotiq_3f_gripper_visualization/meshes/robotiq-3f-gripper_articulated/collision/link_1.STL"/>
      </geometry>
      <material name="yellow"/>
    </collision>
    <inertial>
      <origin rpy="0 0 0" xyz="0 0 0"/>
      <mass value="0.15"/>
      <inertia ixx="0.001859" ixy="-0.000376" ixz="0.000028" iyy="0.012756" iyz="0" izz="0.0024"/>
    </inertial>
  </link>
  <link name="amiga_gripper_finger_1_link_2">
    <!--
			NOTE: This link has an offset in the z-direction based on the models that were
			used to generate grap-it poses.  With the offset below the model appears visually
			correct, but it is suspect.
			-->
    <visual>
      <origin rpy="0 0 0" xyz="0.039 0 0.0075"/>
      <geometry>
        <mesh filename="package://robotiq_3f_gripper_visualization/meshes/robotiq-3f-gripper_articulated/visual/link_2.dae"/>
      </geometry>
      <material name="gray"/>
    </visual>
    <collision>
      <origin rpy="0 0 0" xyz="0.039 0 0.0075"/>
      <geometry>
        <mesh filename="package://robotiq_3f_gripper_visualization/meshes/robotiq-3f-gripper_articulated/collision/link_2.STL"/>
      </geometry>
      <material name="yellow"/>
    </collision>
    <inertial>
      <origin rpy="0 0 0" xyz="0 0 0"/>
      <mass value="0.15"/>
      <inertia ixx="0.001859" ixy="-0.000376" ixz="0.000028" iyy="0.012756" iyz="0" izz="0.0024"/>
    </inertial>
  </link>
  <link name="amiga_gripper_finger_1_link_3">
    <visual>
      <origin rpy="0 0 0.52" xyz="0 0 0"/>
      <geometry>
        <mesh filename="package://robotiq_3f_gripper_visualization/meshes/robotiq-3f-gripper_articulated/visual/link_3.dae"/>
      </geometry>
      <material name="gray"/>
    </visual>
    <collision>
      <origin rpy="0 0 0.52" xyz="0 0 0"/>
      <geometry>
        <mesh filename="package://robotiq_3f_gripper_visualization/meshes/robotiq-3f-gripper_articulated/collision/link_3.STL"/>
      </geometry>
      <material name="yellow"/>
    </collision>
    <inertial>
      <origin rpy="0 0 0" xyz="0 0 0"/>
      <mass value="0.05"/>
      <inertia ixx="0.001239" ixy="-0.000251" ixz="0.000019" iyy="0.00085" iyz="0" izz="0.001632"/>
    </inertial>
  </link>
  <!-- end of link list -->
  <!-- joint list -->
  <joint name="amiga_gripper_finger_1_joint_1" type="revolute">
    <parent link="amiga_gripper_finger_1_link_0"/>
    <child link="amiga_gripper_finger_1_link_1"/>
    <axis xyz="0 0 1"/>
    <origin rpy="0 0 0" xyz="0.020 0 0"/>
    <limit effort="100" lower="0.0495" upper="1.2218" velocity="100"/>
  </joint>
  <joint name="amiga_gripper_finger_1_joint_2" type="revolute">
    <parent link="amiga_gripper_finger_1_link_1"/>
    <child link="amiga_gripper_finger_1_link_2"/>
    <axis xyz="0 0 1"/>
    <origin rpy="0 0 -0.52" xyz="0.050 -.028 0"/>
    <limit effort="100" lower="0.0" upper="1.5708" velocity="100"/>
  </joint>
  <joint name="amiga_gripper_finger_1_joint_3" type="revolute">
    <parent link="amiga_gripper_finger_1_link_2"/>
    <child link="amiga_gripper_finger_1_link_3"/>
    <axis xyz="0 0 1"/>
    <origin rpy="0 0 0" xyz="0.039 0 0"/>
    <limit effort="100" lower="-1.2217" upper="-0.0523" velocity="100"/>
  </joint>
  <!-- end of joint list -->
  <!-- link list -->
  <link name="amiga_gripper_finger_2_link_0">
    <visual>
      <origin rpy="0 0 0" xyz="0.020 0 0"/>
      <geometry>
        <mesh filename="package://robotiq_3f_gripper_visualization/meshes/robotiq-3f-gripper_articulated/visual/link_0.dae"/>
      </geometry>
      <material name="gray">
        <color rgba="0.2 0.2 0.2 1"/>
      </material>
    </visual>
    <collision>
      <origin rpy="0 0 0" xyz="0.020 0 0"/>
      <geometry>
        <mesh filename="package://robotiq_3f_gripper_visualization/meshes/robotiq-3f-gripper_articulated/collision/link_0.STL"/>
      </geometry>
      <material name="yellow">
        <color rgba="0 1 1 1"/>
      </material>
    </collision>
    <inertial>
      <origin rpy="0 0 0" xyz="0 0 0"/>
      <mass value="0.05"/>
      <inertia ixx="0.01" ixy="-0.00002" ixz="0.00001" iyy="0.0008" iyz="0" izz="0.001"/>
    </inertial>
  </link>
  <link name="amiga_gripper_finger_2_link_1">
    <visual>
      <origin rpy="0 0 -0.52" xyz="0.050 -.028 0"/>
      <geometry>
        <mesh filename="package://robotiq_3f_gripper_visualization/meshes/robotiq-3f-gripper_articulated/visual/link_1.dae"/>
      </geometry>
      <material name="gray"/>
    </visual>
    <collision>
      <origin rpy="0 0 -0.52" xyz="0.050 -.028 0"/>
      <geometry>
        <mesh filename="package://robotiq_3f_gripper_visualization/meshes/robotiq-3f-gripper_articulated/collision/link_1.STL"/>
      </geometry>
      <material name="yellow"/>
    </collision>
    <inertial>
      <origin rpy="0 0 0" xyz="0 0 0"/>
      <mass value="0.15"/>
      <inertia ixx="0.001859" ixy="-0.000376" ixz="0.000028" iyy="0.012756" iyz="0" izz="0.0024"/>
    </inertial>
  </link>
  <link name="amiga_gripper_finger_2_link_2">
    <!--
			NOTE: This link has an offset in the z-direction based on the models that were
			used to generate grap-it poses.  With the offset below the model appears visually
			correct, but it is suspect.
			-->
    <visual>
      <origin rpy="0 0 0" xyz="0.039 0 0.0075"/>
      <geometry>
        <mesh filename="package://robotiq_3f_gripper_visualization/meshes/robotiq-3f-gripper_articulated/visual/link_2.dae"/>
      </geometry>
      <material name="gray"/>
    </visual>
    <collision>
      <origin rpy="0 0 0" xyz="0.039 0 0.0075"/>
      <geometry>
        <mesh filename="package://robotiq_3f_gripper_visualization/meshes/robotiq-3f-gripper_articulated/collision/link_2.STL"/>
      </geometry>
      <material name="yellow"/>
    </collision>
    <inertial>
      <origin rpy="0 0 0" xyz="0 0 0"/>
      <mass value="0.15"/>
      <inertia ixx="0.001859" ixy="-0.000376" ixz="0.000028" iyy="0.012756" iyz="0" izz="0.0024"/>
    </inertial>
  </link>
  <link name="amiga_gripper_finger_2_link_3">
    <visual>
      <origin rpy="0 0 0.52" xyz="0 0 0"/>
      <geometry>
        <mesh filename="package://robotiq_3f_gripper_visualization/meshes/robotiq-3f-gripper_articulated/visual/link_3.dae"/>
      </geometry>
      <material name="gray"/>
    </visual>
    <collision>
      <origin rpy="0 0 0.52" xyz="0 0 0"/>
      <geometry>
        <mesh filename="package://robotiq_3f_gripper_visualization/meshes/robotiq-3f-gripper_articulated/collision/link_3.STL"/>
      </geometry>
      <material name="yellow"/>
    </collision>
    <inertial>
      <origin rpy="0 0 0" xyz="0 0 0"/>
      <mass value="0.05"/>
      <inertia ixx="0.001239" ixy="-0.000251" ixz="0.000019" iyy="0.00085" iyz="0" izz="0.001632"/>
    </inertial>
  </link>
  <!-- end of link list -->
  <!-- joint list -->
  <joint name="amiga_gripper_finger_2_joint_1" type="revolute">
    <parent link="amiga_gripper_finger_2_link_0"/>
    <child link="amiga_gripper_finger_2_link_1"/>
    <axis xyz="0 0 1"/>
    <origin rpy="0 0 0" xyz="0.020 0 0"/>
    <limit effort="100" lower="0.0495" upper="1.2218" velocity="100"/>
  </joint>
  <joint name="amiga_gripper_finger_2_joint_2" type="revolute">
    <parent link="amiga_gripper_finger_2_link_1"/>
    <child link="amiga_gripper_finger_2_link_2"/>
    <axis xyz="0 0 1"/>
    <origin rpy="0 0 -0.52" xyz="0.050 -.028 0"/>
    <limit effort="100" lower="0.0" upper="1.5708" velocity="100"/>
  </joint>
  <joint name="amiga_gripper_finger_2_joint_3" type="revolute">
    <parent link="amiga_gripper_finger_2_link_2"/>
    <child link="amiga_gripper_finger_2_link_3"/>
    <axis xyz="0 0 1"/>
    <origin rpy="0 0 0" xyz="0.039 0 0"/>
    <limit effort="100" lower="-1.2217" upper="-0.0523" velocity="100"/>
  </joint>
  <!-- end of joint list -->
  <!-- link list -->
  <link name="amiga_gripper_finger_middle_link_0">
    <visual>
      <origin rpy="0 0 0" xyz="0.020 0 0"/>
      <geometry>
        <mesh filename="package://robotiq_3f_gripper_visualization/meshes/robotiq-3f-gripper_articulated/visual/link_0.dae"/>
      </geometry>
      <material name="gray">
        <color rgba="0.2 0.2 0.2 1"/>
      </material>
    </visual>
    <collision>
      <origin rpy="0 0 0" xyz="0.020 0 0"/>
      <geometry>
        <mesh filename="package://robotiq_3f_gripper_visualization/meshes/robotiq-3f-gripper_articulated/collision/link_0.STL"/>
      </geometry>
      <material name="yellow">
        <color rgba="0 1 1 1"/>
      </material>
    </collision>
    <inertial>
      <origin rpy="0 0 0" xyz="0 0 0"/>
      <mass value="0.05"/>
      <inertia ixx="0.01" ixy="-0.00002" ixz="0.00001" iyy="0.0008" iyz="0" izz="0.001"/>
    </inertial>
  </link>
  <link name="amiga_gripper_finger_middle_link_1">
    <visual>
      <origin rpy="0 0 -0.52" xyz="0.050 -.028 0"/>
      <geometry>
        <mesh filename="package://robotiq_3f_gripper_visualization/meshes/robotiq-3f-gripper_articulated/visual/link_1.dae"/>
      </geometry>
      <material name="gray"/>
    </visual>
    <collision>
      <origin rpy="0 0 -0.52" xyz="0.050 -.028 0"/>
      <geometry>
        <mesh filename="package://robotiq_3f_gripper_visualization/meshes/robotiq-3f-gripper_articulated/collision/link_1.STL"/>
      </geometry>
      <material name="yellow"/>
    </collision>
    <inertial>
      <origin rpy="0 0 0" xyz="0 0 0"/>
      <mass value="0.15"/>
      <inertia ixx="0.001859" ixy="-0.000376" ixz="0.000028" iyy="0.012756" iyz="0" izz="0.0024"/>
    </inertial>
  </link>
  <link name="amiga_gripper_finger_middle_link_2">
    <!--
			NOTE: This link has an offset in the z-direction based on the models that were
			used to generate grap-it poses.  With the offset below the model appears visually
			correct, but it is suspect.
			-->
    <visual>
      <origin rpy="0 0 0" xyz="0.039 0 0.0075"/>
      <geometry>
        <mesh filename="package://robotiq_3f_gripper_visualization/meshes/robotiq-3f-gripper_articulated/visual/link_2.dae"/>
      </geometry>
      <material name="gray"/>
    </visual>
    <collision>
      <origin rpy="0 0 0" xyz="0.039 0 0.0075"/>
      <geometry>
        <mesh filename="package://robotiq_3f_gripper_visualization/meshes/robotiq-3f-gripper_articulated/collision/link_2.STL"/>
      </geometry>
      <material name="yellow"/>
    </collision>
    <inertial>
      <origin rpy="0 0 0" xyz="0 0 0"/>
      <mass value="0.15"/>
      <inertia ixx="0.001859" ixy="-0.000376" ixz="0.000028" iyy="0.012756" iyz="0" izz="0.0024"/>
    </inertial>
  </link>
  <link name="amiga_gripper_finger_middle_link_3">
    <visual>
      <origin rpy="0 0 0.52" xyz="0 0 0"/>
      <geometry>
        <mesh filename="package://robotiq_3f_gripper_visualization/meshes/robotiq-3f-gripper_articulated/visual/link_3.dae"/>
      </geometry>
      <material name="gray"/>
    </visual>
    <collision>
      <origin rpy="0 0 0.52" xyz="0 0 0"/>
      <geometry>
        <mesh filename="package://robotiq_3f_gripper_visualization/meshes/robotiq-3f-gripper_articulated/collision/link_3.STL"/>
      </geometry>
      <material name="yellow"/>
    </collision>
    <inertial>
      <origin rpy="0 0 0" xyz="0 0 0"/>
      <mass value="0.05"/>
      <inertia ixx="0.001239" ixy="-0.000251" ixz="0.000019" iyy="0.00085" iyz="0" izz="0.001632"/>
    </inertial>
  </link>
  <!-- end of link list -->
  <!-- joint list -->
  <joint name="amiga_gripper_finger_middle_joint_1" type="revolute">
    <parent link="amiga_gripper_finger_middle_link_0"/>
    <child link="amiga_gripper_finger_middle_link_1"/>
    <axis xyz="0 0 1"/>
    <origin rpy="0 0 0" xyz="0.020 0 0"/>
    <limit effort="100" lower="0.0495" upper="1.2218" velocity="100"/>
  </joint>
  <joint name="amiga_gripper_finger_middle_joint_2" type="revolute">
    <parent link="amiga_gripper_finger_middle_link_1"/>
    <child link="amiga_gripper_finger_middle_link_2"/>
    <axis xyz="0 0 1"/>
    <origin rpy="0 0 -0.52" xyz="0.050 -.028 0"/>
    <limit effort="100" lower="0.0" upper="1.5708" velocity="100"/>
  </joint>
  <joint name="amiga_gripper_finger_middle_joint_3" type="revolute">
    <parent link="amiga_gripper_finger_middle_link_2"/>
    <child link="amiga_gripper_finger_middle_link_3"/>
    <axis xyz="0 0 1"/>
    <origin rpy="0 0 0" xyz="0.039 0 0"/>
    <limit effort="100" lower="-1.2217" upper="-0.0523" velocity="100"/>
  </joint>
  <!-- end of joint list -->
  <!-- link list -->
  <link name="amiga_gripper_palm">
    <visual>
      <geometry>
        <mesh filename="package://robotiq_3f_gripper_visualization/meshes/robotiq-3f-gripper_articulated/visual/palm.dae"/>
      </geometry>
      <material name="gray">
        <color rgba="0.2 0.2 0.2 1"/>
      </material>
    </visual>
    <collision>
      <geometry>
        <mesh filename="package://robotiq_3f_gripper_visualization/meshes/robotiq-3f-gripper_articulated/collision/palm.STL"/>
      </geometry>
      <material name="yellow">
        <color rgba="0 1 1 1"/>
      </material>
    </collision>
  </link>
  <link name="amiga_gripper_tool0"/>
  <inertial>
    <origin rpy="0 0 0" xyz="0 0 0"/>
    <mass value="1.3"/>
    <inertia ixx="0.006012" ixy="0.000079" ixz="-0.00024" iyy="0.012892" iyz="0" izz="0.002435"/>
  </inertial>
  <!-- end of link list -->
  <!-- joint list -->
  <joint name="amiga_gripper_palm_finger_1_joint" type="revolute">
    <parent link="amiga_gripper_palm"/>
    <child link="amiga_gripper_finger_1_link_0"/>
    <axis xyz="0 1 0"/>
    <origin rpy="0 3.1416 -1.57" xyz="-0.0455 0.0214 0.036"/>
    <limit effort="100" lower="-0.1784" upper="0.192" velocity="100"/>
  </joint>
  <joint name="amiga_gripper_palm_finger_2_joint" type="revolute">
    <parent link="amiga_gripper_palm"/>
    <child link="amiga_gripper_finger_2_link_0"/>
    <axis xyz="0 1 0"/>
    <origin rpy="0 3.1416 -1.57" xyz="-0.0455 0.0214 -0.036"/>
    <limit effort="100" lower="-0.192" upper="0.1784" velocity="100"/>
  </joint>
  <joint name="amiga_gripper_palm_finger_middle_joint" type="fixed">
    <parent link="amiga_gripper_palm"/>
    <child link="amiga_gripper_finger_middle_link_0"/>
    <axis xyz="0 0 1"/>
    <origin rpy="0 0 1.57" xyz="0.0455 0.0214 0"/>
  </joint>
  <joint name="amiga_gripper_palm_tool0" type="fixed">
    <parent link="amiga_gripper_palm"/>
    <child link="amiga_gripper_tool0"/>
    <origin rpy="0 0 1.5707" xyz="0.0 0.0875 0.0"/>
  </joint>
  <!-- end of joint list -->
  <link name="amiga_grip_camera_mount_base_link">
    <inertial>
      <origin rpy="0 0 0" xyz="4.5207E-19 0.035453 -6.5774E-05"/>
      <mass value="0.11943"/>
      <inertia ixx="0.00015472" ixy="5.0596E-20" ixz="1.5989E-20" iyy="0.00010796" iyz="6.9683E-07" izz="0.00024696"/>
    </inertial>
    <visual>
      <origin rpy="0 0 0" xyz="0 0 0"/>
      <geometry>
        <mesh filename="package://amiga_description/robots/meshes/base_link.STL"/>
      </geometry>
      <material name="">
        <color rgba="0.25098 0.25098 0.25098 1"/>
      </material>
    </visual>
    <collision>
      <origin rpy="0 0 0" xyz="0 0 0"/>
      <geometry>
        <mesh filename="package://amiga_description/robots/meshes/base_link.STL"/>
      </geometry>
    </collision>
  </link>
  <!-- Camera mounting point (the threaded screw hole in the bottom) -->
  <link name="zed2_base_link"/>
  <joint name="zed2_base_joint" type="fixed">
    <parent link="amiga_arm_tool0"/>
    <child link="zed2_base_link"/>
    <origin rpy="-0.025 -1.315 -2.356" xyz="0.091 0.088 0.030"/>
  </joint>
  <!-- Camera Center -->
  <link name="zed2_camera_center">
    <visual>
      <origin rpy="0 0 0" xyz="0.0 0 0"/>
      <geometry>
        <mesh filename="package://amiga_description/robots/meshes/zed2.stl"/>
      </geometry>
      <material name="zed2_mat"/>
    </visual>
    <collision>
      <geometry>
        <mesh filename="package://amiga_description/robots/meshes/zed2.stl"/>
      </geometry>
    </collision>
  </link>
  <joint name="zed2_camera_center_joint" type="fixed">
    <parent link="zed2_base_link"/>
    <child link="zed2_camera_center"/>
    <origin rpy="0 0.05 0" xyz="0 0 0.015"/>
  </joint>
  <!-- Left Camera -->
  <link name="zed2_left_camera_frame"/>
  <joint name="zed2_left_camera_joint" type="fixed">
    <parent link="zed2_camera_center"/>
    <child link="zed2_left_camera_frame"/>
    <origin rpy="0 0 0" xyz="0 0.06 0"/>
  </joint>
  <link name="zed2_left_camera_optical_frame"/>
  <joint name="zed2_left_camera_optical_joint" type="fixed">
    <origin rpy="-1.5707963267948966 0.0 -1.5707963267948966" xyz="-0.01 0 0"/>
    <parent link="zed2_left_camera_frame"/>
    <child link="zed2_left_camera_optical_frame"/>
  </joint>
  <!-- Right Camera -->
  <link name="zed2_right_camera_frame"/>
  <joint name="zed2_right_camera_joint" type="fixed">
    <parent link="zed2_camera_center"/>
    <child link="zed2_right_camera_frame"/>
    <origin rpy="0 0 0" xyz="0 -0.06 0"/>
  </joint>
  <link name="zed2_right_camera_optical_frame"/>
  <joint name="zed2_right_camera_optical_joint" type="fixed">
    <origin rpy="-1.5707963267948966 0.0 -1.5707963267948966" xyz="-0.01 0 0"/>
    <parent link="zed2_right_camera_frame"/>
    <child link="zed2_right_camera_optical_frame"/>
  </joint>
  <link name="zed2_mag_link"/>
  <joint name="zed2_mag_joint" type="fixed">
    <parent link="zed2_camera_center"/>
    <child link="zed2_mag_link"/>
    <origin rpy="0 0 0" xyz="0 0 0"/>
  </joint>
  <link name="zed2_baro_link"/>
  <joint name="zed2_baro_joint" type="fixed">
    <parent link="zed2_camera_center"/>
    <child link="zed2_baro_link"/>
    <origin rpy="0 0 0" xyz="0 0 0"/>
  </joint>
  <link name="zed2_temp_left_link"/>
  <joint name="zed2_temp_left_joint" type="fixed">
    <parent link="zed2_left_camera_frame"/>
    <child link="zed2_temp_left_link"/>
    <origin rpy="0 0 0" xyz="0 0 0"/>
  </joint>
  <link name="zed2_temp_right_link"/>
  <joint name="zed2_temp_right_joint" type="fixed">
    <parent link="zed2_right_camera_frame"/>
    <child link="zed2_temp_right_link"/>
    <origin rpy="0 0 0" xyz="0 0 0"/>
  </joint>
  <joint name="base_arm_joint" type="fixed">
    <origin rpy="0 0 -1.5705" xyz="0 0 0.3"/>
    <axis xyz="0 0 0"/>
    <parent link="base_link"/>
    <child link="amiga_arm_base_link"/>
  </joint>
  <joint name="arm_gripper_joint" type="fixed">
    <origin rpy="1.5708 0 -0.785398" xyz="0 0 0.1"/>
    <parent link="amiga_arm_tool0"/>
    <child link="amiga_gripper_palm"/>
  </joint>
  <joint name="amig_arm_wrist_3_link-amiga_grip_camera_mount_link" type="fixed">
    <!-- <origin xyz="0 0 0.0129" rpy="1.5708 3.14159 2.356192" /> -->
    <origin rpy="0 -2.35619 3.14159" xyz="0 0.15 0"/>
    <parent link="amiga_arm_wrist_3_link"/>
    <child link="amiga_grip_camera_mount_base_link"/>
  </joint>
  <!-- <joint name="l515_gripper_joint" type="fixed"> -->
  <!-- visual with amiga_grip_camera_mount_base_link-->
  <!-- <origin xyz="0 -0.013 0.146" rpy="0 0.349066 -1.5708"/> -->
  <!-- 220304 -->
  <!-- <origin xyz="0.139445 0.123489 0.0607699" rpy="0.2472 -1.1802 -2.6403"/> -->
  <!-- 220304v2 -->
  <!-- <origin xyz="0.1409 0.1037 0.0487" rpy="0.2674 -1.1115 -2.7397"/> -->
  <!-- 220307 -->
  <!-- <origin xyz="0.1195 0.1129 0.0225" rpy="-0.1991 -1.2091 -2.1717"/> -->
  <!-- <parent link="amiga_arm_tool0" />
        <child link="l515_grip_link" />
    </joint> -->
</robot>

